use crate::client_connection::ClientConnection;
use crate::results::{Column, QueryResults, QueryStats};
use crate::{PrestinoError, Headers};
use async_stream::try_stream;
use futures::Stream;
use futures_util::pin_mut;
use serde::de::DeserializeOwned;
use std::time::{Duration, Instant};

pub struct StatementExecutor<T: DeserializeOwned> {
    id: String,
    headers: Headers,
    connection: Box<dyn ClientConnection>,
    results: QueryResults<T>,
    next_run_time: Instant,
}

impl<T: DeserializeOwned> StatementExecutor<T> {
    pub(crate) fn new(
        id: String,
        headers: Headers,
        connection: impl ClientConnection + 'static,
        results: QueryResults<T>,
    ) -> Self {
        Self {
            id,
            headers,
            connection: Box::new(connection),
            results,
            next_run_time: Instant::now(),
        }
    }

    pub fn id(&self) -> &str {
        &self.id
    }

    pub fn info_uri(&self) -> &str {
        &self.results.info_uri
    }

    pub fn columns(&self) -> Option<&[Column]> {
        self.results.columns.as_deref()
    }

    pub fn stats(&self) -> &QueryStats {
        &self.results.stats
    }

    /// Cancel execution of this statement.  If the query is already finished,
    /// return PrestinoError::QueryFinishedError with the query id.
    pub async fn cancel(mut self) -> Result<(), PrestinoError> {
        let Some(next_uri) = self.results.next_uri.take() else {
            return Err(PrestinoError::QueryFinishedError(self.id().to_owned()));
        };

        // TODO: If this is an HTTP error, we should probably try again, or at least
        // allow the caller to try again.
        self.connection.cancel(&next_uri, &mut self.headers).await
    }

    pub async fn next_response(&mut self) -> Option<Result<Vec<T>, PrestinoError>> {
        // Clear out any data that we've saved.
        if let Some(err) = self.results.error.take() {
            return Some(Err(err.into()));
        } else if let Some(rows) = self.results.data.take() {
            return Some(Ok(rows));
        }

        if let Some(delta) = self.next_run_time.checked_duration_since(Instant::now()) {
            // We still need to wait before we can call again
            async_std::task::sleep(delta).await;
        }

        // If there is no next_uri, we have finished iteration.
        let next_uri = self.results.next_uri.take()?;
        let result_bytes = match self.connection.get_next_results(&next_uri, &mut self.headers).await {
            Err(PrestinoError::StatusCodeError(503, _)) => {
                // Server is overloaded and needs 100ms:
                // https://trino.io/docs/current/develop/client-protocol.html#overview-of-query-processing
                self.bump_next_run_time();
                self.results.next_uri = Some(next_uri);
                return Some(Ok(Vec::new()));
            }
            Err(err) => return Some(Err(err)),
            Ok(results) => results,
        };
        // TODO: Make better error messages on json deser.  In particular, if there's a type error,
        // can we print out the row that causes the error?
        self.results = match parse_results(&result_bytes) {
            Ok(res) => res,
            Err(e) => return Some(Err(e)),
        };

        if let Some(err) = self.results.error.take() {
            return Some(Err(err.into()));
        }
        let rows = match self.results.data.take() {
            Some(r) => {
                if r.is_empty() {
                    self.bump_next_run_time();
                }
                r
            }
            None => {
                self.bump_next_run_time();
                Vec::new()
            }
        };
        Some(Ok(rows))
    }

    fn bump_next_run_time(&mut self) {
        self.next_run_time = Instant::now() + Duration::from_millis(100);
    }

    pub fn responses(mut self) -> impl Stream<Item = Result<(Vec<T>, QueryStats), PrestinoError>> {
        try_stream! {
            while let Some(response) = self.next_response().await {
                yield (response?, self.results.stats.clone());
            }
        }
    }

    pub fn batches(self) -> impl Stream<Item = Result<Vec<T>, PrestinoError>> {
        try_stream! {
            let query_results = self.responses();
            pin_mut!(query_results);
            for await rows_result in query_results {
                let rows = rows_result?.0;
                if !rows.is_empty() {
                    yield rows;
                }
            }
        }
    }

    pub fn rows(self) -> impl Stream<Item = Result<T, PrestinoError>> {
        try_stream! {
            let batches = self.batches();
            pin_mut!(batches);
            for await batch in batches {
                for row in batch?.drain(..) {
                    yield row;
                }
            }
        }
    }
}

fn parse_results<T: DeserializeOwned>(bytes: &[u8]) -> Result<T, PrestinoError> {
        // TODO: Make better error messages on json deser.  In particular, if there's a type error,
        // can we print out the row that causes the error?
        match serde_json::from_slice(&bytes) {
            Ok(res) => Ok(res),
            Err(err) => return Err(PrestinoError::from(err)),
        }
}
